<mujoco model="go1_description">
    <compiler angle="radian" meshdir="../meshes/" />
    <size njmax="500" nconmax="100" />
    <!-- <option  timestep="0.01"/> -->
    <!-- <option gravity='0 0 -9.806' iterations='150' solver='Newton' timestep='0.000000001' integrator='RK4'/> -->
    <!-- <option gravity='0 0 -9.806' iterations='150' solver='Newton' timestep='0.000000001' integrator='Euler'/> -->
    <!-- <option gravity='0 0 -9.806' iterations='20' solver='Newton' timestep='0.000001' integrator='Euler'/> -->
    <!-- <option gravity='0 0 -9.806' iterations='20' solver='Newton' timestep='0.002' integrator='Euler'/> -->
    <!-- <option gravity='0 0 -9.806' iterations='50' solver='Newton' timestep='0.0000001' integrator='implicitfast'/> -->
    <option gravity='0 0 -9.806' iterations='50' solver='Newton' timestep='0.002'/>

    <default>
        <!-- <ge###om contype="1" conaffinity="1" friction="1.0 1.0 1.0" rgba="0.5 0.6 0.7 1" margin="0.001" group="0"/> -->
        <geom contype="1" conaffinity="1" friction='1 0.5 0.5' rgba="0.5 0.6 0.7 1" margin="0.001" group="0" density="50000.0" condim='3'/>
        

        <light castshadow="false" diffuse="1 1 1"/>
        <motor ctrlrange="-33.5 33.5" ctrllimited="true"/>
        <!-- <camera fovy="80"/> -->
        <joint damping=".01" armature=".01" frictionloss="0.2" />
        
    </default>

    <custom>
        <numeric name="sensor_size" data="0.05" />
    </custom>

    <asset>
        <mesh name="trunk" file="trunk.stl" />
        <mesh name="hip" file="hip.stl" />
        <mesh name="thigh_mirror" file="thigh_mirror.stl" />
        <mesh name="calf" file="calf.stl" />
        <mesh name="thigh" file="thigh.stl" />
        <mesh name="sensor_body" file="sensor_body.stl" />
        <!-- <mesh name="stairs1" file="Stairs.stl" scale='1 1 1' /> -->
    </asset>

    <asset>
        <texture type="skybox" builtin="gradient" rgb1="1.0 1.0 1.0" rgb2="1.0 1.0 1.0" width="512" height="512"/>
        <texture name="plane" type="2d" builtin="flat" rgb1="1 1 1" rgb2="1 1 1" width="512" height="512" mark="cross" markrgb="0 0 0"/>
        <material name="plane" reflectance="0.0" texture="plane" texrepeat="3 3" texuniform="true"/>
    </asset>

        <!-- <asset>
            <touch name="foot_contact" site="0.01" />
        </asset> -->

    <asset>
        <!-- <hfield name="hf1" size="10 10 0.3 0.1" file="C:\\Users\\Omri\\Desktop\\MSc\\Thesis\\Code\\Height_Maps\\heightmap1682612500.9804645.png"/>        
        <texture name="height_map_texture" type="2d" file="C:\\Users\\Omri\\Desktop\\MSc\\Thesis\\Code\\Height_Maps\\heightmap1682612500.9804645.png" /> -->
        <!-- <hfield name="hf1" size="9 9 0.7 0.1" file="C:\\Users\\Omri\\Desktop\\MSc\\Thesis\\Code\\Height_Maps\\heightmap1685995019.9920268.png"/>        
        <texture name="height_map_texture" type="2d" file="C:\\Users\\Omri\\Desktop\\MSc\\Thesis\\Code\\Height_Maps\\heightmap1685995019.9920268.png" /> -->
        <!-- <hfield name="hf1" size="40 40 2.4 0.1" file="C:\\Users\\Omri\\Desktop\\MSc\\Thesis\\Code\\Height_Maps\\heightmap1685995019.9920268.png"/>        
        <texture name="height_map_texture" type="2d" file="C:\\Users\\Omri\\Desktop\\MSc\\Thesis\\Code\\Height_Maps\\heightmap1685995019.9920268.png" /> -->
         <hfield name="hf1" size="40 40 2.6 0.1" file="C:\\Users\\Omri\\Desktop\\MSc\\Thesis\\Code\\Height_Maps\\heightmap1685995019.9920268_resized.png"/>        
        <!-- <texture name="height_map_texture" type="2d" file="C:\\Users\\Omri\\Desktop\\MSc\\Thesis\\Code\\Height_Maps\\heightmap1685995019.9920268_resized.png" /> -->
        <!-- <hfield name="hf1" size="40 40 2.4 0.1" file="C:\\Users\\Omri\\Desktop\\MSc\\Thesis\\Code\\Height_Maps\\stairs_done.png"/>        
        <texture name="height_map_texture" type="2d" file="C:\\Users\\Omri\\Desktop\\MSc\\Thesis\\Code\\Height_Maps\\stairs_done.png" /> -->
        <!-- <hfield name="hf1" size="25 25 2.5 0.1" file="C:\\Users\\Omri\\Desktop\\MSc\\Thesis\\Code\\Height_Maps\\Zero.png"/>        
        <texture name="height_map_texture" type="2d" file="C:\\Users\\Omri\\Desktop\\MSc\\Thesis\\Code\\Height_Maps\\Zero.png" /> -->
        <!-- <hfield name="hf1" size="9 9 0.20 0.1" file="C:\\Users\\Omri\\Desktop\\MSc\\Thesis\\Code\\Height_Maps\\heightmap1687160443.5383704.png"/>        
        <texture name="height_map_texture" type="2d" file="C:\\Users\\Omri\\Desktop\\MSc\\Thesis\\Code\\Height_Maps\\heightmap1687160443.5383704.png" /> -->
        <!-- <hfield name="hf1" size="9 9 0.22 0.1" file="C:\\Users\\Omri\\Desktop\\MSc\\Thesis\\Code\\Height_Maps\\heightmap1687431432.2127147_zeroed.png"/>        
        <texture name="height_map_texture" type="2d" file="C:\\Users\\Omri\\Desktop\\MSc\\Thesis\\Code\\Height_Maps\\heightmap1687431432.2127147_zeroed.png" /> -->
        <!-- <hfield name="myhfield" file="C:\\Users\\Omri\\Desktop\\MSc\Thesis\\Code\\Height_Maps\\stairs_done.png" size="1 1 3 0.1"/> -->
    </asset>

    <visual>
        <rgba com="0.502 1.0 0 0.5" contactforce="0.98 0.4 0.4 0.7" contactpoint="1.0 1.0 0.6 0.4"/>
        <scale com="0.2" forcewidth="0.035" contactwidth="0.10" contactheight="0.04"/>
    </visual>

    <worldbody>
        <light directional="true" diffuse=".8 .8 .8" pos="0 0 10" dir="0 0 -10"/>
        <!-- <camera name="track" mode="trackcom" pos="0 -1.3 1.6" xyaxes="1 0 0 0 0.707 0.707"/> -->
        <!-- <geom name='floor' type='plane' conaffinity='1' condim='3' contype='1' rgba="0.5 0.9 0.9 0.1" material='plane' pos='0 0 0' size='0 0 1'/> -->
        <!-- <site name="_sensor" pos="0 0 0" size="0.0305" rgba="1 0 0 1" type="sphere" /> -->
        <geom name="hfield1" type="hfield" hfield="hf1" rgba="0.5 0.9 0.9 0.7" material='plane' pos='0 0 0'/>
        <!-- <geom type="hfield" name="staircase_hfield" pos="0 0 0" size="1 1 1" nrow="4" ncol="4" data="0 0 0 0 0 1 1 1 0 2 2 2 0 3 3 3"/> -->
        <!-- <geom name="hfield0" type="hfield" hfield="myhfield" pos="0 0 0" size="1 1 1"/> -->
        <!-- <geom name="hfield1" type="hfield" hfield="hf1" size="1 1 1" conaffinity='1' condim='3' contype='1' rgba="0.5 0.9 0.9 0.7" material='plane' pos='0 0 -1' group='0'/> -->
        <!-- <body name="stairs" pos='0.7 -0.5 0'> -->
        <!-- <geom name="stairs" type="mesh" pos='0.3 -0.5 0' group='0' contype="1" conaffinity="2" priority='1' rgba="0.213725 0.913725 0.247059 1" mesh="stairs1" material='plane'/> -->

        <!-- <body name="trunk" pos="0.0 0 0.385"> -->
        <body name="trunk" pos="0.0 0 0.20189675">
            <camera name="track" mode="trackcom" pos="0 -1.3 1.6" xyaxes="1 0 0 0 0.707 0.707"/>
            <inertial pos="0.0116053 0.00442221 0.000106692" quat="0.0111438 0.707126 -0.00935374 0.706938" mass="4.801" diaginertia="0.0447997 0.0366257 0.0162187" />
            <joint type="free" />
            <geom name="trunk" type="mesh" contype="0" conaffinity="0" group="1" rgba="0.913725 0.913725 0.847059 1" mesh="trunk" />
            <geom name="trunk1" contype="0" conaffinity="0" size="0.13 0.04675 0.057" type="box" rgba="0.913725 0.913725 0.847059 1" />
            <geom name="trunk2" size="0.0005 0.0005 0.0005" pos="-0.01592 -0.06659 -0.00617" type="box" contype="0" conaffinity="0" group="1" rgba="0.8 0 0 0" />
            <!-- <geom size="0.0005 0.0005 0.0005" pos="-0.01592 -0.06659 -0.00617" type="box" rgba="0.8 0 0 0" /> -->
            <site name="imu" pos="0 0 0"/>

            <body name="FR_hip" pos="0.1881 -0.04675 0">
                <!-- <inertial pos="-0.00406411 -0.0193463 4.50733e-06" quat="0.467526 0.531662 -0.466259 0.530431" mass="0.001" diaginertia="0.00131334 0.00122648 0.000728484" /> -->
                <inertial pos="-0.00406411 -0.0193463 4.50733e-06" quat="0.467526 0.531662 -0.466259 0.530431" mass="0.679292" diaginertia="0.00131334 0.00122648 0.000728484" />
                <joint name="FR_hip_joint" pos="0 0 0" axis="1 0 0" limited="true" range="-0.802851 0.802851" />
                <!-- <joint name="FR_hip_joint" pos="0 0 0" axis="1 0 0" limited="true" range="-0.202851 0.202851" /> -->
                <geom name="FR_hip" quat="0 1 0 0" type="mesh" contype="0" conaffinity="0" group="1" rgba="0.913725 0.913725 0.847059 1" mesh="hip" />
                <geom name="FR_hip1" size="0.046 0.02" pos="0 -0.045 0" quat="0.707107 0.707107 0 0" type="cylinder" rgba="0.913725 0.913725 0.847059 0" />
                <geom name="FR_hip2" size="0.031 0.02" pos="0 -0.07 0" quat="0.707107 0.707107 0 0" type="cylinder" rgba="0.913725 0.913725 0.847059 0" />

                <body name="FR_thigh" pos="0 -0.08 0">
                    <inertial pos="-0.003468 0.018947 -0.032736" quat="0.999266 0.00067676 -0.0382978 0.000639813" mass="0.898919" diaginertia="0.00542178 0.00514246 0.000998869" />
                    <!-- <inertial pos="-0.003468 0.018947 -0.032736" quat="0.999266 0.00067676 -0.0382978 0.000639813" mass="0.001" diaginertia="0.00542178 0.00514246 0.000998869" /> -->
                    <joint name="FR_thigh_joint" pos="0 0 0" axis="0 1 0" limited="true" range="-1.0472 4.18879" />
                    <!-- <joint name="FR_thigh_joint" pos="0 0 0" axis="0 1 0" limited="true" range="-0.2472 1.08879" /> -->
                    <geom name="FR_thigh" type="mesh" contype="0" conaffinity="0" group="1" rgba="0.913725 0.913725 0.847059 1" mesh="thigh_mirror" />
                    <geom name="FR_thigh1" size="0.1065 0.01225 0.017" pos="0 0 -0.1065" quat="0.707107 0 0.707107 0" type="box" rgba="0.913725 0.913725 0.847059 0" />
                    
                    <body name="FR_calf" pos="0 0 -0.213">
                        <inertial pos="0.00455603 0.0009473 -0.147239" quat="0.762045 0.00970173 0.0180098 0.647201" mass="0.218015" diaginertia="0.00399678 0.00398122 3.99428e-05" />
                        <!-- <inertial pos="0.00455603 0.0009473 -0.147239" quat="0.762045 0.00970173 0.0180098 0.647201" mass="0.001" diaginertia="0.00399678 0.00398122 3.99428e-05" /> -->
                        <joint name="FR_calf_joint" pos="0 0 0" axis="0 1 0" limited="true" range="-2.69653 -0.916298" />
                        <!-- <joint name="FR_calf_joint" pos="0 0 0" axis="0 1 0" limited="true" range="-0.69653 -0.316298" /> -->
                        <geom name="FR_calf1" type="mesh" contype="0" conaffinity="0" group="1" rgba="0 0 0 1" mesh="calf" />
                        <geom name="FR_calf2" size="0.1065 0.008 0.008" pos="0 0 -0.1065" quat="0.707107 0 0.707107 0" type="box" rgba="0 0 0 0" />
                        <geom name="FR_calf3" size="0.01" pos="0 0 -0.213" contype="0" conaffinity="0" group="1" rgba="0 0 0 1" />
                        <geom name="FR_calf" size="0.02" pos="0 0 -0.213" rgba="0 0 0 1" />
                        <site name="FR_force_sensor" pos="0 0 -0.215" size="0.0005" rgba="1 0 0 1" type="sphere" />
                        <site name="FR_touch_sensor" pos="0 0 -0.215" size="0.0005" rgba="1 0 0 1" type="sphere" />
                        <!-- <site name="FR_touch_sensor" pos="0 0 0" size="0.0305" rgba="1 0 0 1" type="sphere" /> -->
                        <!-- <ge###om name="FR_sensor" pos="0 0 -0.2" type="mesh" mesh="sensor_body" rgba="1 0 0 1" /> -->
                    </body>
                </body>
            </body>
            
            <body name="FL_hip" pos="0.1881 0.04675 0">
                <inertial pos="-0.00406411 0.0193463 4.50733e-06" quat="0.531662 0.467526 -0.530431 0.466259" mass="0.679292" diaginertia="0.00131334 0.00122648 0.000728484" />
                <!-- <inertial pos="-0.00406411 0.0193463 4.50733e-06" quat="0.531662 0.467526 -0.530431 0.466259" mass="0.001" diaginertia="0.00131334 0.00122648 0.000728484" /> -->
                <joint name="FL_hip_joint" pos="0 0 0" axis="1 0 0" limited="true" range="-0.802851 0.802851" />
                <!-- <joint name="FL_hip_joint" pos="0 0 0" axis="1 0 0" limited="true" range="-0.202851 0.202851" /> -->
                <geom name="FL_hip" type="mesh" contype="0" conaffinity="0" group="1" rgba="0.913725 0.913725 0.847059 1" mesh="hip" />
                <geom name="FL_hip1" size="0.046 0.02" pos="0 0.045 0" quat="0.707107 0.707107 0 0" type="cylinder" rgba="0.913725 0.913725 0.847059 0" />
                <geom name="FL_hip2" size="0.031 0.02" pos="0 0.07 0" quat="0.707107 0.707107 0 0" type="cylinder" rgba="0.913725 0.913725 0.847059 0" />

                <body name="FL_thigh" pos="0 0.08 0">
                    <inertial pos="-0.003468 -0.018947 -0.032736" quat="0.999266 -0.00067676 -0.0382978 -0.000639813" mass="0.898919" diaginertia="0.00542178 0.00514246 0.000998869" />
                    <!-- <inertial pos="-0.003468 -0.018947 -0.032736" quat="0.999266 -0.00067676 -0.0382978 -0.000639813" mass="0.001" diaginertia="0.00542178 0.00514246 0.000998869" /> -->
                    <joint name="FL_thigh_joint" pos="0 0 0" axis="0 1 0" limited="true" range="-1.0472 4.18879" />
                    <!-- <joint name="FL_thigh_joint" pos="0 0 0" axis="0 1 0" limited="true" range="-0.2472 1.08879" /> -->
                    <geom name="FL_thigh" type="mesh" contype="0" conaffinity="0" group="1" rgba="0.913725 0.913725 0.847059 1" mesh="thigh" />
                    <geom name="FL_thigh1" size="0.1065 0.01225 0.017" pos="0 0 -0.1065" quat="0.707107 0 0.707107 0" type="box" rgba="0.913725 0.913725 0.847059 0" />
                    
                    <body name="FL_calf" pos="0 0 -0.213">
                        <inertial pos="0.00455603 0.0009473 -0.147239" quat="0.762045 0.00970173 0.0180098 0.647201" mass="0.218015" diaginertia="0.00399678 0.00398122 3.99428e-05" />
                        <!-- <inertial pos="0.00455603 0.0009473 -0.147239" quat="0.762045 0.00970173 0.0180098 0.647201" mass="0.001" diaginertia="0.00399678 0.00398122 3.99428e-05" /> -->
                        <joint name="FL_calf_joint" pos="0 0 0" axis="0 1 0" limited="true" range="-2.69653 -0.916298" />
                        <!-- <joint name="FL_calf_joint" pos="0 0 0" axis="0 1 0" limited="true" range="-0.69653 -0.316298" /> -->
                        <geom name= "FL_calf1" type="mesh" contype="0" conaffinity="0" group="1" rgba="0 0 0 1" mesh="calf" />
                        <geom name= "FL_calf2" size="0.1065 0.008 0.008" pos="0 0 -0.1065" quat="0.707107 0 0.707107 0" type="box" rgba="0.913725 0.913725 0.847059 0" />
                        <geom name= "FL_calf3" size="0.01" pos="0 0 -0.213" contype="0" conaffinity="0" group="1" rgba="0 0 0 1" />
                        <geom name= "FL_calf" size="0.02" pos="0 0 -0.213" rgba="0 0 0 1" />
                        <site name="FL_force_sensor" pos="0 0 -0.215" size="0.0005" rgba="1 0 0 1" type="sphere" />
                        <site name="FL_touch_sensor" pos="0 0 -0.215" size="0.0005" rgba="1 0 0 1" type="sphere" />
                    </body>
                </body>
            </body>
            
            <body name="RR_hip" pos="-0.1881 -0.04675 0">
                <inertial pos="0.00406411 -0.0193463 4.50733e-06" quat="0.530431 0.466259 -0.531662 0.467526" mass="0.679292" diaginertia="0.00131334 0.00122648 0.000728484" />
                <!-- <inertial pos="0.00406411 -0.0193463 4.50733e-06" quat="0.530431 0.466259 -0.531662 0.467526" mass="0.001" diaginertia="0.00131334 0.00122648 0.000728484" /> -->
                <joint name="RR_hip_joint" pos="0 0 0" axis="1 0 0" limited="true" range="-0.802851 0.802851" />
                <!-- <joint name="RR_hip_joint" pos="0 0 0" axis="1 0 0" limited="true" range="-0.202851 0.202851" /> -->
                <geom name="RR_hip" quat="0 0 0 -1" type="mesh" contype="0" conaffinity="0" group="1" rgba="0.913725 0.913725 0.847059 1" mesh="hip" />
                <!-- <geom size="0.046 0.02" quat="0.707107 0.707107 0 0" type="cylinder" rgba="0.913725 0.913725 0.847059 1" /> -->
                <geom name="RR_hip1" size="0.046 0.02" pos="0 -0.045 0" quat="0.707107 0.707107 0 0" type="cylinder" rgba="0.913725 0.913725 0.847059 0" />
                <geom name="RR_hip2" size="0.031 0.02" pos="0 -0.07 0" quat="0.707107 0.707107 0 0" type="cylinder" rgba="0.913725 0.913725 0.847059 0" />
        
                <body name="RR_thigh" pos="0 -0.08 0">
                    <inertial pos="-0.003468 0.018947 -0.032736" quat="0.999266 0.00067676 -0.0382978 0.000639813" mass="0.898919" diaginertia="0.00542178 0.00514246 0.000998869" />
                    <!-- <inertial pos="-0.003468 0.018947 -0.032736" quat="0.999266 0.00067676 -0.0382978 0.000639813" mass="0.001" diaginertia="0.00542178 0.00514246 0.000998869" /> -->
                    <joint name="RR_thigh_joint" pos="0 0 0" axis="0 1 0" limited="true" range="-1.0472 4.18879" />
                    <!-- <joint name="RR_thigh_joint" pos="0 0 0" axis="0 1 0" limited="true" range="-0.2472 1.08879" /> -->
                    <geom name="RR_thigh" type="mesh" contype="0" conaffinity="0" group="1" rgba="0.913725 0.913725 0.847059 1" mesh="thigh_mirror" />
                    <geom name="RR_thigh1" size="0.1065 0.01225 0.017" pos="0 0 -0.1065" quat="0.707107 0 0.707107 0" type="box" rgba="0.913725 0.913725 0.847059 0" />
                    
                    <body name="RR_calf" pos="0 0 -0.213">
                        <inertial pos="0.00455603 0.0009473 -0.147239" quat="0.762045 0.00970173 0.0180098 0.647201" mass="0.218015" diaginertia="0.00399678 0.00398122 3.99428e-05" />
                        <!-- <inertial pos="0.00455603 0.0009473 -0.147239" quat="0.762045 0.00970173 0.0180098 0.647201" mass="0.001" diaginertia="0.00399678 0.00398122 3.99428e-05" /> -->
                        <joint name="RR_calf_joint" pos="0 0 0" axis="0 1 0" limited="true" range="-2.69653 -0.916298" />
                        <!-- <joint name="RR_calf_joint" pos="0 0 0" axis="0 1 0" limited="true" range="-0.69653 -0.316298" /> -->
                        <geom name="RR_calf1" type="mesh" contype="0" conaffinity="0" group="1" rgba="0 0 0 1" mesh="calf" />
                        <geom name="RR_calf2" size="0.1065 0.008 0.008" pos="0 0 -0.1065" quat="0.707107 0 0.707107 0" type="box" rgba="0 0 0 0" />
                        <geom name="RR_calf3" size="0.01" pos="0 0 -0.213" contype="0" conaffinity="0" group="1" rgba="0 0 0 1" />
                        <geom name="RR_calf" size="0.02" pos="0 0 -0.213" rgba="0 0 0 1" />
                        <site name="RR_force_sensor" pos="0 0 -0.215" size="0.0005" rgba="1 0 0 1" type="sphere" />
                        <site name="RR_touch_sensor" pos="0 0 -0.215" size="0.0005" rgba="1 0 0 1" type="sphere" />
                    </body>
                </body>
            </body>
            <body name="RL_hip" pos="-0.1881 0.04675 0">
                <inertial pos="0.00406411 0.0193463 4.50733e-06" quat="0.466259 0.530431 -0.467526 0.531662" mass="0.679292" diaginertia="0.00131334 0.00122648 0.000728484" />
                <!-- <inertial pos="0.00406411 0.0193463 4.50733e-06" quat="0.466259 0.530431 -0.467526 0.531662" mass="0.001" diaginertia="0.00131334 0.00122648 0.000728484" /> -->
                <joint name="RL_hip_joint" pos="0 0 0" axis="1 0 0" limited="true" range="-0.802851 0.802851"  />
                <!-- <joint name="RL_hip_joint" pos="0 0 0" axis="1 0 0" limited="true" range="-0.202851 0.202851"  /> -->
                <geom name="RL_hip" quat="0 0 1 0" type="mesh" contype="0" conaffinity="0" group="1" rgba="0.913725 0.913725 0.847059 1" mesh="hip" />
                <!-- <geom size="0.046 0.02" quat="0.707107 0.707107 0 0" type="cylinder" rgba="0.913725 0.913725 0.847059 1" /> -->
                <geom name="RL_hip1" size="0.046 0.02" pos="0 0.045 0" quat="0.707107 0.707107 0 0" type="cylinder" rgba="0.913725 0.913725 0.847059 0" />
                <geom name="RL_hip2" size="0.031 0.02" pos="0 0.07 0" quat="0.707107 0.707107 0 0" type="cylinder" rgba="0.913725 0.913725 0.847059 0" />

                <body name="RL_thigh" pos="0 0.08 0">
                    <inertial pos="-0.003468 -0.018947 -0.032736" quat="0.999266 -0.00067676 -0.0382978 -0.000639813" mass="0.898919" diaginertia="0.00542178 0.00514246 0.000998869" />
                    <!-- <inertial pos="-0.003468 -0.018947 -0.032736" quat="0.999266 -0.00067676 -0.0382978 -0.000639813" mass="0.001" diaginertia="0.00542178 0.00514246 0.000998869" /> -->
                    <joint name="RL_thigh_joint" pos="0 0 0" axis="0 1 0" limited="true" range="-1.0472 4.18879" />
                    <!-- <joint name="RL_thigh_joint" pos="0 0 0" axis="0 1 0" limited="true" range="-0.2472 1.08879" /> -->
                    <geom name="RL_thigh" type="mesh" contype="0" conaffinity="0" group="1" rgba="0.913725 0.913725 0.847059 1" mesh="thigh" />
                    <geom name="RL_thigh1" size="0.1065 0.01225 0.017" pos="0 0 -0.1065" quat="0.707107 0 0.707107 0" type="box" rgba="0.913725 0.913725 0.847059 0" />
                    
                    <body name="RL_calf" pos="0 0 -0.213">
                        <inertial pos="0.00455603 0.0009473 -0.147239" quat="0.762045 0.00970173 0.0180098 0.647201" mass="0.218015" diaginertia="0.00399678 0.00398122 3.99428e-05" />
                        <!-- <inertial pos="0.00455603 0.0009473 -0.147239" quat="0.762045 0.00970173 0.0180098 0.647201" mass="0.001" diaginertia="0.00399678 0.00398122 3.99428e-05" /> -->
                        <joint name="RL_calf_joint" pos="0 0 0" axis="0 1 0" limited="true" range="-2.69653 -0.916298" />
                        <!-- <joint name="RL_calf_joint" pos="0 0 0" axis="0 1 0" limited="true" range="-0.69653 -0.316298" /> -->
                        <geom name="RL_calf1" type="mesh" contype="0" conaffinity="0" group="1" rgba="0 0 0 1" mesh="calf" />
                        <geom name="RL_calf2" size="0.1065 0.008 0.008" pos="0 0 -0.1065" quat="0.707107 0 0.707107 0" type="box" rgba="0 0 0 0" />
                        <geom name="RL_calf3" size="0.01" pos="0 0 -0.213" contype="0" conaffinity="0" group="1" rgba="0 0 0 1" />
                        <geom name="RL_calf" size="0.02" pos="0 0 -0.213" rgba="0 0 0 1" />
                        <site name="RL_force_sensor" pos="0 0 -0.215" size="0.0005" rgba="1 0 0 1" type="sphere" />
                        <site name="RL_touch_sensor" pos="0 0 -0.215" size="0.0005" rgba="1 0 0 1" type="sphere" />
                    </body>
                </body>
            </body>
        </body>
    </worldbody>
    <actuator>       
        
        <motor name="FR_hip"       gear="1" joint="FR_hip_joint"/>
        <motor name="FR_thigh"     gear="1" joint="FR_thigh_joint"/>
        <motor name="FR_calf"      gear="1" joint="FR_calf_joint"/>
        <motor name="FL_hip"       gear="1" joint="FL_hip_joint"/>
        <motor name="FL_thigh"     gear="1" joint="FL_thigh_joint"/>
        <motor name="FL_calf"      gear="1" joint="FL_calf_joint"/>
        <motor name="RR_hip"       gear="1" joint="RR_hip_joint"/>
        <motor name="RR_thigh"     gear="1" joint="RR_thigh_joint"/>
        <motor name="RR_calf"      gear="1" joint="RR_calf_joint" />
        <motor name="RL_hip"       gear="1" joint="RL_hip_joint"/>
        <motor name="RL_thigh"     gear="1" joint="RL_thigh_joint"/>
        <motor name="RL_calf"      gear="1" joint="RL_calf_joint"/>
    </actuator>

    <sensor>

        <jointpos name="FR_hip_pos"     joint="FR_hip_joint"/>
        <jointpos name="FR_thigh_pos"   joint="FR_thigh_joint"/>
        <jointpos name="FR_calf_pos"    joint="FR_calf_joint"/>
        <jointpos name="FL_hip_pos"     joint="FL_hip_joint"/>
        <jointpos name="FL_thigh_pos"   joint="FL_thigh_joint"/>
        <jointpos name="FL_calf_pos"    joint="FL_calf_joint"/>
        <jointpos name="RR_hip_pos"     joint="RR_hip_joint"/>
        <jointpos name="RR_thigh_pos"   joint="RR_thigh_joint"/>
        <jointpos name="RR_calf_pos"    joint="RR_calf_joint" />
        <jointpos name="RL_hip_pos"     joint="RL_hip_joint"/>
        <jointpos name="RL_thigh_pos"   joint="RL_thigh_joint"/>
        <jointpos name="RL_calf_pos"    joint="RL_calf_joint"/>

        <jointvel name="FR_hip_vel"     joint="FR_hip_joint"/>
        <jointvel name="FR_thigh_vel"   joint="FR_thigh_joint"/>
        <jointvel name="FR_calf_vel"    joint="FR_calf_joint"/>
        <jointvel name="FL_hip_vel"     joint="FL_hip_joint"/>
        <jointvel name="FL_thigh_vel"   joint="FL_thigh_joint"/>
        <jointvel name="FL_calf_vel"    joint="FL_calf_joint"/>
        <jointvel name="RR_hip_vel"     joint="RR_hip_joint"/>
        <jointvel name="RR_thigh_vel"   joint="RR_thigh_joint"/>
        <jointvel name="RR_calf_vel"    joint="RR_calf_joint" />
        <jointvel name="RL_hip_vel"     joint="RL_hip_joint"/>
        <jointvel name="RL_thigh_vel"   joint="RL_thigh_joint"/>
        <jointvel name="RL_calf_vel"    joint="RL_calf_joint"/>

        <accelerometer name="Body_Acc" site="imu"/>

        <gyro name="Body_Gyro" site="imu"/>

        <framepos name="Body_Pos" objtype="site" objname="imu"/>

        <framequat name="Body_Quat" objtype="site" objname="imu"/>

        <touch name="FR_touch" site="FR_touch_sensor" />
        <touch name="FL_touch" site="FL_touch_sensor" />
        <touch name="RR_touch" site="RR_touch_sensor" />
        <touch name="RL_touch" site="RL_touch_sensor" />
        <force name="FR_force" site="FR_force_sensor" />
        <force name="FL_force" site="FL_force_sensor" />
        <force name="RR_force" site="RR_force_sensor" />
        <force name="RL_force" site="RL_force_sensor" />
    
    </sensor>
</mujoco>
